<?xml version="1.0" encoding="utf-8"?>
<!-- This URDF was automatically created by SolidWorks to URDF Exporter! Originally created by Stephen Brawner (brawner@gmail.com) 
     Commit Version: 1.6.0-4-g7f85cfe  Build Version: 1.6.7995.38578
     For more information, please see http://wiki.ros.org/sw_urdf_exporter -->
<robot
  name="00-arm-rs_asm-v3">
  <link
    name="base_link">
    <inertial>
      <origin
        xyz="2.87641888266442E-06 -0.000122302488725115 0.0243376121934547"
        rpy="0 0 0" />
      <mass
        value="1.1774" />
      <inertia
        ixx="0.00133040"
        ixy="0.00000001"
        ixz="0.00000000"
        iyy="0.00213119"
        iyz="0.00000000"
        izz="0.00275877" />
    </inertial>
    <visual>
      <origin
        xyz="0 0 0"
        rpy="0 0 0" />
      <geometry>
        <mesh
          filename="package://00-arm-rs_asm-v3/meshes/base_link.STL" />
      </geometry>
      <material
        name="">
        <color
          rgba="0.752941176470588 0.752941176470588 0.752941176470588 1" />
      </material>
    </visual>
    <collision>
      <origin
        xyz="0 0 0"
        rpy="0 0 0" />
      <geometry>
        <mesh
          filename="package://00-arm-rs_asm-v3/meshes/base_link.STL" />
      </geometry>
    </collision>
  </link>
  <link
    name="link1">
    <inertial>
      <origin
        xyz="0.00817652280320541 0.00122584211922395 0.0331419658967293"
        rpy="0 0 0" />
      <mass
        value="0.4655" />
      <inertia
        ixx="0.00025207"
        ixy="0.00000000"
        ixz="-0.00002832"
        iyy="0.00015464"
        iyz="0.00000000"
        izz="0.00023416" />
    </inertial>
    <visual>
      <origin
        xyz="0 0 0"
        rpy="0 0 0" />
      <geometry>
        <mesh
          filename="package://00-arm-rs_asm-v3/meshes/link1.STL" />
      </geometry>
      <material
        name="">
        <color
          rgba="0.752941176470588 0.752941176470588 0.752941176470588 1" />
      </material>
    </visual>
    <collision>
      <origin
        xyz="0 0 0"
        rpy="0 0 0" />
      <geometry>
        <mesh
          filename="package://00-arm-rs_asm-v3/meshes/link1.STL" />
      </geometry>
    </collision>
  </link>
  <joint
    name="joint1"
    type="revolute">
    <origin
      xyz="-0.00034283 -0.00098683 0.075"
      rpy="0 0 0" />
    <parent
      link="base_link" />
    <child
      link="link1" />
    <axis
      xyz="0 0 1" />
    <limit
      lower="-2.8"
      upper="2.8"
      effort="36"
      velocity="50" />
  </joint>
  <link
    name="link2">
    <inertial>
      <origin
        xyz="-0.117864812717456 -0.00342226413942967 -0.0271551938501484"
        rpy="0 0 0" />
      <mass
        value="1.552" />
      <inertia
        ixx="0.000577466775"
        ixy="-3.3841785e-07"
        ixz="6.69752535e-06"
        iyy="0.00988484698"
        iyz="1.00738337e-06"
        izz="0.0100847496" />
    </inertial>
    <!-- <visual>
      <origin
        xyz="0 0 0"
        rpy="0 0 0" />
      <geometry>
        <mesh
          filename="package://00-arm-rs_asm-v3/meshes/link2.STL" />
      </geometry>
      <material
        name="">
        <color
          rgba="0.752941176470588 0.752941176470588 0.752941176470588 1" />
      </material>
    </visual> -->
    <visual>
      <origin
        xyz="0 0 0"
        rpy="0 0 0" />
      <geometry>
        <mesh
          filename="package://00-arm-rs_asm-v3/meshes/motor_2_3.STL" />
      </geometry>
      <material
        name="">
        <color
          rgba="0.752941176470588 0.752941176470588 0.752941176470588 1" />
      </material>
    </visual>
    <visual>
      <origin
        xyz="0 0 0"
        rpy="0 0 0" />
      <geometry>
        <mesh
          filename="package://00-arm-rs_asm-v3/meshes/cnc2.STL" />
      </geometry>
      <material
        name="">
        <color
          rgba="0.752941176470588 0.752941176470588 0.752941176470588 1" />
      </material>
    </visual>
    <visual>
      <origin
        xyz="0 0 0"
        rpy="0 0 0" />
      <geometry>
        <mesh
          filename="package://00-arm-rs_asm-v3/meshes/pla2_black.STL" />
      </geometry>
      <material
        name="">
        <color
          rgba="0.752941176470588 0.752941176470588 0.752941176470588 1" />
      </material>
    </visual>
    <visual>
      <origin
        xyz="0 0 0"
        rpy="0 0 0" />
      <geometry>
        <mesh
          filename="package://00-arm-rs_asm-v3/meshes/pla2_green.STL" />
      </geometry>
      <material
        name="">
        <color
          rgba="0.752941176470588 0.752941176470588 0.752941176470588 1" />
      </material>
    </visual>
    <collision>
      <origin
        xyz="0 0 0"
        rpy="0 0 0" />
      <geometry>
        <mesh
          filename="package://00-arm-rs_asm-v3/meshes/link2.STL" />
      </geometry>
    </collision>
  </link>
  <joint
    name="joint2"
    type="revolute">
    <origin
      xyz="0.020343 0.027237 0.07"
      rpy="-1.5708 0 0" />
    <parent
      link="link1" />
    <child
      link="link2" />
    <axis
      xyz="0 0 -1" />
    <limit
      lower="-3.14"
      upper="0"
      effort="36"
      velocity="50" />
  </joint>
  <link
    name="link3">
    <inertial>
      <origin
        xyz="0.103427154487799 -0.0664137912104635 -0.0271068687716704"
        rpy="0 0 0" />
      <mass
        value="1.252" />
      <inertia
        ixx="0.000551811337"
        ixy="-4.07430508e-05"
        ixz="-5.02214689e-05"
        iyy="0.00745889021"
        iyz="7.07344633e-08"
        izz="0.00764192742" />
    </inertial>
    <!--  <visual>
      <origin
        xyz="0 0 0"
        rpy="0 0 0" />
      <geometry>
        <mesh
          filename="package://00-arm-rs_asm-v3/meshes/link3.STL" />
      </geometry>
      <material
        name="">
        <color
          rgba="0.752941176470588 0.752941176470588 0.752941176470588 1" />
      </material>
    </visual> -->
    <visual>
      <origin
        xyz="0 0 0"
        rpy="0 0 0" />
      <geometry>
        <mesh
          filename="package://00-arm-rs_asm-v3/meshes/cnc3.STL" />
      </geometry>
      <material
        name="">
        <color
          rgba="0.752941176470588 0.752941176470588 0.752941176470588 1" />
      </material>
    </visual>
    <visual>
      <origin
        xyz="0 0 0"
        rpy="0 0 0" />
      <geometry>
        <mesh
          filename="package://00-arm-rs_asm-v3/meshes/motor_4.STL" />
      </geometry>
      <material
        name="">
        <color
          rgba="0.752941176470588 0.752941176470588 0.752941176470588 1" />
      </material>
    </visual>
    <visual>
      <origin
        xyz="0 0 0"
        rpy="0 0 0" />
      <geometry>
        <mesh
          filename="package://00-arm-rs_asm-v3/meshes/pla3_black.STL" />
      </geometry>
      <material
        name="">
        <color
          rgba="0.752941176470588 0.752941176470588 0.752941176470588 1" />
      </material>
    </visual>
    <visual>
      <origin
        xyz="0 0 0"
        rpy="0 0 0" />
      <geometry>
        <mesh
          filename="package://00-arm-rs_asm-v3/meshes/pla3_green.STL" />
      </geometry>
      <material
        name="">
        <color
          rgba="0.752941176470588 0.752941176470588 0.752941176470588 1" />
      </material>
    </visual>
    <collision>
      <origin
        xyz="0 0 0"
        rpy="0 0 0" />
      <geometry>
        <mesh
          filename="package://00-arm-rs_asm-v3/meshes/link3.STL" />
      </geometry>
    </collision>
  </link>
  <joint
    name="joint3"
    type="revolute">
    <origin
      xyz="-0.236 0 0"
      rpy="0 0 0" />
    <parent
      link="link2" />
    <child
      link="link3" />
    <axis
      xyz="0 0 1" />
    <limit
      lower="-3.14"
      upper="0"
      effort="36"
      velocity="50" />
  </joint>
  <link
    name="link4">
    <inertial>
      <origin
        xyz="0.0475544540775559 -0.0441113470158517 -0.0314111924918381"
        rpy="0 0 0" />
      <mass
        value="0.46" />
      <inertia
        ixx="0.000320508485"
        ixy="0.000168799091"
        ixz="-0"
        iyy="0.000524525455"
        iyz="-0"
        izz="0.000465171515" />
    </inertial>
    <!-- <visual>
      <origin
        xyz="0 0 0"
        rpy="0 0 0" />
      <geometry>
        <mesh
          filename="package://00-arm-rs_asm-v3/meshes/link4.STL" />
      </geometry>
      <material
        name="">
        <color
          rgba="0.752941176470588 0.752941176470588 0.752941176470588 1" />
      </material>
    </visual> -->
    <visual>
      <origin
        xyz="0 0 0"
        rpy="0 0 0" />
      <geometry>
        <mesh
          filename="package://00-arm-rs_asm-v3/meshes/motor_5.STL" />
      </geometry>
      <material
        name="">
        <color
          rgba="0.752941176470588 0.752941176470588 0.752941176470588 1" />
      </material>
    </visual>
    <visual>
      <origin
        xyz="0 0 0"
        rpy="0 0 0" />
      <geometry>
        <mesh
          filename="package://00-arm-rs_asm-v3/meshes/cnc4.STL" />
      </geometry>
      <material
        name="">
        <color
          rgba="0.752941176470588 0.752941176470588 0.752941176470588 1" />
      </material>
    </visual>
    <collision>
      <origin
        xyz="0 0 0"
        rpy="0 0 0" />
      <geometry>
        <mesh
          filename="package://00-arm-rs_asm-v3/meshes/link4.STL" />
      </geometry>
    </collision>
  </link>
  <joint
    name="joint4"
    type="revolute">
    <origin
      xyz="0.228 -0.072746 0.0045"
      rpy="0 0 0" />
    <parent
      link="link3" />
    <child
      link="link4" />
    <axis
      xyz="0 0 1" />
    <limit
      lower="-1.79"
      upper="1.69"
      effort="14"
      velocity="40" />
  </joint>
  <link
    name="link5">
    <inertial>
      <origin
        xyz="-0.0114400622356175 4.7907739316217E-06 0.0480487481818926"
        rpy="0 0 0" />
      <mass
        value="0.20120457182895" />
      <inertia
        ixx="9.84090046e-05"
        ixy="1.81878283e-08"
        ixz="-1.15016294e-06"
        iyy="7.39220615e-05"
        iyz="-1.77912637e-08"
        izz="7.10245279e-05" />
    </inertial>
    <!-- <visual>
      <origin
        xyz="0 0 0"
        rpy="0 0 0" />
      <geometry>
        <mesh
          filename="package://00-arm-rs_asm-v3/meshes/link5.STL" />
      </geometry>
      <material
        name="">
        <color
          rgba="0.752941176470588 0.752941176470588 0.752941176470588 1" />
      </material>
    </visual> -->
    <visual>
      <origin
        xyz="0 0 0"
        rpy="0 0 0" />
      <geometry>
        <mesh
          filename="package://00-arm-rs_asm-v3/meshes/motor_6.STL" />
      </geometry>
      <material
        name="">
        <color
          rgba="0.752941176470588 0.752941176470588 0.752941176470588 1" />
      </material>
    </visual>
    <visual>
      <origin
        xyz="0 0 0"
        rpy="0 0 0" />
      <geometry>
        <mesh
          filename="package://00-arm-rs_asm-v3/meshes/cnc5.STL" />
      </geometry>
      <material
        name="">
        <color
          rgba="0.752941176470588 0.752941176470588 0.752941176470588 1" />
      </material>
    </visual>
    <visual>
      <origin
        xyz="0 0 0"
        rpy="0 0 0" />
      <geometry>
        <mesh
          filename="package://00-arm-rs_asm-v3/meshes/pla5_green.STL" />
      </geometry>
      <material
        name="">
        <color
          rgba="0.752941176470588 0.752941176470588 0.752941176470588 1" />
      </material>
    </visual>
    <collision>
      <origin
        xyz="0 0 0"
        rpy="0 0 0" />
      <geometry>
        <mesh
          filename="package://00-arm-rs_asm-v3/meshes/link5.STL" />
      </geometry>
    </collision>
  </link>
  <joint
    name="joint5"
    type="revolute">
    <origin
      xyz="0.087 -0.048 -0.03075"
      rpy="-1.5708 0 0" />
    <parent
      link="link4" />
    <child
      link="link5" />
    <axis
      xyz="0 0 1" />
    <limit
      lower="-1.57"
      upper="1.57"
      effort="14"
      velocity="40" />
  </joint>
  <link
    name="link6">
    <inertial>
      <origin
        xyz="1.80196022567525E-05 2.48334592051007E-08 0.00434805764057547"
        rpy="0 0 0" />
      <mass
        value="0.1" />
      <inertia
        ixx="1.47424612e-05"
        ixy="1.05586155e-11"
        ixz="5.06176061e-10"
        iyy="1.45728507e-05"
        iyz="-7.39546725e-12"
        izz="2.8476646e-05" />
    </inertial>
    <visual>
      <origin
        xyz="0 0 0"
        rpy="0 0 0" />
      <geometry>
        <mesh
          filename="package://00-arm-rs_asm-v3/meshes/link6.STL" />
      </geometry>
      <material
        name="">
        <color
          rgba="0.752941176470588 0.752941176470588 0.752941176470588 1" />
      </material>
    </visual>
    <collision>
      <origin
        xyz="0 0 0"
        rpy="0 0 0" />
      <geometry>
        <mesh
          filename="package://00-arm-rs_asm-v3/meshes/link6.STL" />
      </geometry>
    </collision>
  </link>
  <joint
    name="joint6"
    type="revolute">
    <origin
      xyz="0.0365 0 0.048"
      rpy="0 1.5708 0" />
    <parent
      link="link5" />
    <child
      link="link6" />
    <axis
      xyz="0 0 1" />
    <limit
      lower="-3.14"
      upper="3.14"
      effort="14"
      velocity="40" />
  </joint>
  <link
    name="gripper_end">
    <inertial>
      <origin
        xyz="-0.112751692515958 0.000128443070436966 -5.72602449749882E-06"
        rpy="0 0 0" />
      <mass
        value="0.65" />
      <inertia
        ixx="0.00037354"
        ixy="-0.00000011"
        ixz="0.00000050"
        iyy="0.00015830"
        iyz="0.00000348"
        izz="0.00045353" />
    </inertial>
    <!-- <visual>
      <origin
        xyz="0 0 0"
        rpy="0 0 0" />
      <geometry>
        <mesh
          filename="package://00-arm-rs_asm-v3/meshes/gripper_end.STL" />
      </geometry>
      <material
        name="">
        <color
          rgba="0.752941176470588 0.752941176470588 0.752941176470588 1" />
      </material>
    </visual> -->
    <visual>
      <origin
        xyz="0 0 0"
        rpy="0 0 0" />
      <geometry>
        <mesh
          filename="package://00-arm-rs_asm-v3/meshes/pla7_green.STL" />
      </geometry>
      <material
        name="">
        <color
          rgba="0.752941176470588 0.752941176470588 0.752941176470588 1" />
      </material>
    </visual>
    <visual>
      <origin
        xyz="0 0 0"
        rpy="0 0 0" />
      <geometry>
        <mesh
          filename="package://00-arm-rs_asm-v3/meshes/cnc7.STL" />
      </geometry>
      <material
        name="">
        <color
          rgba="0.752941176470588 0.752941176470588 0.752941176470588 1" />
      </material>
    </visual>
    <visual>
      <origin
        xyz="0 0 0"
        rpy="0 0 0" />
      <geometry>
        <mesh
          filename="package://00-arm-rs_asm-v3/meshes/motor_7.STL" />
      </geometry>
      <material
        name="">
        <color
          rgba="0.752941176470588 0.752941176470588 0.752941176470588 1" />
      </material>
    </visual>
    <collision>
      <origin
        xyz="0 0 0"
        rpy="0 0 0" />
      <geometry>
        <mesh
          filename="package://00-arm-rs_asm-v3/meshes/gripper_end.STL" />
      </geometry>
    </collision>
  </link>
  <joint
    name="j_gripper_end"
    type="fixed">
    <origin
      xyz="0 0 0.16621"
      rpy="3.1416 -1.5708 0" />
    <parent
      link="link6" />
    <child
      link="gripper_end" />
    <axis
      xyz="0 0 0" />
  </joint>
  <link
    name="gripper_left">
    <inertial>
      <origin
        xyz="-0.00218008703135955 0.0187090355934181 0.00932188568692145"
        rpy="0 0 0" />
      <mass
        value="0.0752" />
      <inertia
        ixx="1.09877964176176E-05"
        ixy="0"
        ixz="0"
        iyy="9.50146036720166E-06"
        iyz="0"
        izz="9.30779991911125E-06" />
    </inertial>
    <!-- <visual>
      <origin
        xyz="0 0 0"
        rpy="0 0 0" />
      <geometry>
        <mesh
          filename="package://00-arm-rs_asm-v3/meshes/gripper_left.STL" />
      </geometry>
      <material
        name="">
        <color
          rgba="0.752941176470588 0.752941176470588 0.752941176470588 1" />
      </material>
    </visual> -->
    <visual>
      <origin
        xyz="0 0 0"
        rpy="0 0 0" />
      <geometry>
        <mesh
          filename="package://00-arm-rs_asm-v3/meshes/pla_left.STL" />
      </geometry>
      <material
        name="">
        <color
          rgba="0.752941176470588 0.752941176470588 0.752941176470588 1" />
      </material>
    </visual>
    <visual>
      <origin
        xyz="0 0 0"
        rpy="0 0 0" />
      <geometry>
        <mesh
          filename="package://00-arm-rs_asm-v3/meshes/cnc_left.STL" />
      </geometry>
      <material
        name="">
        <color
          rgba="0.752941176470588 0.752941176470588 0.752941176470588 1" />
      </material>
    </visual>
    <collision>
      <origin
        xyz="0 0 0"
        rpy="0 0 0" />
      <geometry>
        <mesh
          filename="package://00-arm-rs_asm-v3/meshes/gripper_left.STL" />
      </geometry>
    </collision>
  </link>
  <joint
    name="joint_left"
    type="prismatic">
    <origin
      xyz="-0.041939 -7.3385E-05 0"
      rpy="1.5708 -1.5708 0" />
    <parent
      link="gripper_end" />
    <child
      link="gripper_left" />
    <axis
      xyz="0 0 1" />
    <limit
      lower="0"
      upper="0.05"
      effort="500"
      velocity="10" />
  </joint>
  <link
    name="gripper_right">
    <inertial>
      <origin
        xyz="0.00218008703135955 -0.018709035593418 0.00932188568692151"
        rpy="0 0 0" />
      <mass
        value="0.0752" />
      <inertia
        ixx="1.09877964176176E-05"
        ixy="0"
        ixz="0"
        iyy="9.50146036720166E-06"
        iyz="0"
        izz="9.30779991911125E-06" />
    </inertial>
    <!-- <visual>
      <origin
        xyz="0 0 0"
        rpy="0 0 0" />
      <geometry>
        <mesh
          filename="package://00-arm-rs_asm-v3/meshes/gripper_right.STL" />
      </geometry>
      <material
        name="">
        <color
          rgba="0.752941176470588 0.752941176470588 0.752941176470588 1" />
      </material>
    </visual> -->
    <visual>
      <origin
        xyz="0 0 0"
        rpy="0 0 0" />
      <geometry>
        <mesh
          filename="package://00-arm-rs_asm-v3/meshes/pla_right.STL" />
      </geometry>
      <material
        name="">
        <color
          rgba="0.752941176470588 0.752941176470588 0.752941176470588 1" />
      </material>
    </visual>
    <visual>
      <origin
        xyz="0 0 0"
        rpy="0 0 0" />
      <geometry>
        <mesh
          filename="package://00-arm-rs_asm-v3/meshes/cnc_right.STL" />
      </geometry>
      <material
        name="">
        <color
          rgba="0.752941176470588 0.752941176470588 0.752941176470588 1" />
      </material>
    </visual>
    <collision>
      <origin
        xyz="0 0 0"
        rpy="0 0 0" />
      <geometry>
        <mesh
          filename="package://00-arm-rs_asm-v3/meshes/gripper_right.STL" />
      </geometry>
    </collision>
  </link>
  <joint
    name="joint_right"
    type="prismatic">
    <origin
      xyz="-0.041939 7.3385E-05 0"
      rpy="-1.5708 -1.5708 0" />
    <parent
      link="gripper_end" />
    <child
      link="gripper_right" />
    <axis
      xyz="0 0 1" />
    <limit
      lower="0"
      upper="0.0715"
      effort="500"
      velocity="10" />
  </joint>
</robot>
